Workbook

Sheet Cleaned
A1: CITY | B1: Population | C1: QCODE | D1: Region | E1: How often are bills issued? - Selected Choice | F1: How often are bills issued? - Other (Please Specify) - Text | G1: What methods of payment are accepted? (Check all that apply) [Cash] | H1: What methods of payment are accepted? (Check all that apply) [Check] | I1: What methods of payment are accepted? (Check all that apply) [Credit/Debit] | J1: What methods of payment are accepted? (Check all that apply) [Direct Deposit] | K1: What methods of payment are accepted? (Check all that apply) [Money Order] | L1: What methods of payment are accepted? (Check all that apply) [e-check] | M1: Do you provide paperless billing? | N1: What methods of enforcement are used for late or nonpayments? (Check all that Apply) - Selected Choice [Collections] | O1: What methods of enforcement are used for late or nonpayments? (Check all that Apply) - Selected Choice [Disconnect Water Service] | P1: What methods of enforcement are used for late or nonpayments? (Check all that Apply) - Selected Choice [Late Fee] | Q1: What methods of enforcement are used for late or nonpayments? (Check all that Apply) - Selected Choice [Late Fee and Interest] | R1: What methods of enforcement are used for late or nonpayments? (Check all that Apply) - Selected Choice [Lien on Property] | S1: What methods of enforcement are used for late or nonpayments? (Check all that Apply) - Selected Choice [Other (Please Specify)] | T1: What methods of enforcement are used for late or nonpayments? (Check all that Apply) - Other (Please Specify) - Text | U1: What is the late fee rate? | V1: What is the interest rate? | W1: How many days past due date are allowed before the late fee is assessed? | X1: What is the penalties amount and interest rate? - Penalties Amount | Y1: What is the penalties amount and interest rate? - Interest Rate | Z1: How many days after due date before you disconnect water service? | AA1: What dollar amount or number of days late triggers collections? - Dollar Amount | AB1: What dollar amount or number of days late triggers collections? - Days | AC1: Does the city provide waivers, discounts or reductions to certain utility customers? | AD1: Please describe these waivers, discounts and reductions: | AE1: Does your city provide credit or make any billing adjustments for leaks or billing errors? | AF1: For what services are adjustments made for customer water leaks | AG1: If a leak is detected, how far back does the city make adjustments to the water bill? - Days | AH1: If a leak is detected, how far back does the city make adjustments to the water bill? - Other Comments | AI1: Please describe what you do for wastewater adjustments. | AJ1: What percentage of rate revenue is obligated to debt services for the following systems? - Rate Revenue - Water - % | AK1: What percentage of rate revenue is obligated to debt services for the following systems? - Rate Revenue - Wastewater - % | AL1: What percentage of rate revenue is obligated to debt services for the following systems? - Rate Revenue - Stormwater - % | AM1: What percentage of rate revenue is obligated to debt services for the following systems? - Not Applicable - Water | AN1: What percentage of rate revenue is obligated to debt services for the following systems? - Not Applicable - Wastewater | AO1: What percentage of rate revenue is obligated to debt services for the following systems? - Not Applicable - Stormwater | AP1: Does your city maintain an asset management system for the following services? - Water | AQ1: Does your city maintain an asset management system for the following services? - Wastewater | AR1: Does your city maintain an asset management system for the following services? - Stormwater | AS1: What was the last year you did a Rate Study for the following services? - Water | AT1: What was the last year you did a Rate Study for the following services? - Wastewater | AU1: What was the last year you did a Rate Study for the following services? - Stormwater | AV1: What was the last year you did a Methodology Update for the following services? - Water | AW1: What was the last year you did a Methodology Update for the following services? - Wastewater | AX1: What was the last year you did a Methodology Update for the following services? - Stormwater | AY1: Does your city require accounts to be in the name of the property owner? | AZ1: How does your city handle billing for vacant properties? - Selected Choice | BA1: How does your city handle billing for vacant properties? - Charge a vacant rate upon request of the owner. (Please Explain) - Text | BB1: How does your city handle billing for vacant properties? - Other (Please Specify) - Text | BC1: What other account fees or charges are included on the utility bill? (Check all that apply) - Selected Choice [Backflow] | BD1: What other account fees or charges are included on the utility bill? (Check all that apply) - Selected Choice [New Account] | BE1: What other account fees or charges are included on the utility bill? (Check all that apply) - Selected Choice [None] | BF1: What other account fees or charges are included on the utility bill? (Check all that apply) - Selected Choice [Other (Please Specify)] | BG1: What other account fees or charges are included on the utility bill? (Check all that apply) - Selected Choice [Shutoff] | BH1: What other account fees or charges are included on the utility bill? (Check all that apply) - Selected Choice [Tampering] | BI1: What other account fees or charges are included on the utility bill? (Check all that apply) - Other (Please Specify) - Text | BJ1: Is stormwater included in the utility bill? | BK1: What general government fees are included on the utility bill? (Check all that apply) - Selected Choice [Fire] | BL1: What general government fees are included on the utility bill? (Check all that apply) - Selected Choice [Library] | BM1: What general government fees are included on the utility bill? (Check all that apply) - Selected Choice [Other (Please Specify)] | BN1: What general government fees are included on the utility bill? (Check all that apply) - Selected Choice [Parks & Recreation] | BO1: What general government fees are included on the utility bill? (Check all that apply) - Selected Choice [Police] | BP1: What general government fees are included on the utility bill? (Check all that apply) - Selected Choice [Streets & Streetlights] | BQ1: What general government fees are included on the utility bill? (Check all that apply) - Selected Choice [Surface Water Management] | BR1: What general government fees are included on the utility bill? (Check all that apply) - Other (Please Specify) - Text | BS1: Does city ordinance have an automatic CPI/Income adjustment for the following services? - Water | BT1: Does city ordinance have an automatic CPI/Income adjustment for the following services? - Wastewater | BU1: Does city ordinance have an automatic CPI/Income adjustment for the following services? - Stormwater | BV1: Does your city charge for drinking water service? | BW1: What was the last effective date of your city's most recent rate change for water services? (Please respond with the year only) | BX1: Overall, did the rate increase or decrease at the most recent rate change? Please also include the percent (%) change. - Selected Choice | BY1: Overall, did the rate increase or decrease at the most recent rate change? Please also include the percent (%) change. - Increase (% Increase) - Text | BZ1: Why did the city change water rates? (Check all that apply) - Selected Choice [Capital Improvement] | CA1: Why did the city change water rates? (Check all that apply) - Selected Choice [Inflation/ CPI] | CB1: Why did the city change water rates? (Check all that apply) - Selected Choice [Labor Costs] | CC1: Why did the city change water rates? (Check all that apply) - Selected Choice [Other (Please Specify)] | CD1: Why did the city change water rates? (Check all that apply) - Selected Choice [State/ Federal Mandate] | CE1: Why did the city change water rates? (Check all that apply) - Selected Choice [Treatment Costs] | CF1: Why did the city change water rates? (Check all that apply) - Other (Please Specify) - Text | CG1: What is the rate structure for your city's water service? - Selected Choice | CH1: What is the rate structure for your city's water service? - Other (Please Specify) - Text | CI1: For water services, if you were to bill a residential customer for 5,000 gallons (6.684 CCFs) with a 3/4'' meter size, what dollar amount would you bill them, including the base rate? | CJ1: Does your city charge for wastewater service? | CK1: What was the last effective date of your city's most recent rate change for wastewater services? (Please respond with the year only) | CL1: Overall, did the rate increase or decrease at the most recent rate change? Please include percent (%) change. - Selected Choice | CM1: Overall, did the rate increase or decrease at the most recent rate change? Please include percent (%) change. - Increase (% Increase) - Text | CN1: Why did the city change wastewater rates? (Check all that apply) - Selected Choice [Capital Improvement] | CO1: Why did the city change wastewater rates? (Check all that apply) - Selected Choice [Inflation/ CPI] | CP1: Why did the city change wastewater rates? (Check all that apply) - Selected Choice [Labor Costs] | CQ1: Why did the city change wastewater rates? (Check all that apply) - Selected Choice [Other (Please Specify)] | CR1: Why did the city change wastewater rates? (Check all that apply) - Selected Choice [State/ Federal Mandate] | CS1: Why did the city change wastewater rates? (Check all that apply) - Selected Choice [Treatment Costs] | CT1: Why did the city change wastewater rates? (Check all that apply) - Other (Please Specify) - Text | CU1: What is the rate structure for your city's wastewater service? - Selected Choice | CV1: What is the rate structure for your city's wastewater service? - Other (Please Specify) - Text | CW1: For wastewater services, if you were to bill a residential customer for 5,000 gallons (6.684 CCFs) with a 3/4'' meter size, what dollar amount would you bill them, including the base rate? | CX1: Does your city charge for stormwater service? | CY1: What was the last effective date of your city's most recent rate change for stormwater services? (Please respond with the year only) | CZ1: Overall, did the rate increase or decrease at the most recent rate change? Please include the percent (%) change. - Selected Choice | DA1: Overall, did the rate increase or decrease at the most recent rate change? Please include the percent (%) change. - Increase (% Increase) - Text | DB1: Is your city subject to an MS4 Phase I or Phase II (DEQ Issued Stormwater) Permit? | DC1: Why did the city change stormwater rates? (Check all that apply) - Selected Choice [Capital Improvement] | DD1: Why did the city change stormwater rates? (Check all that apply) - Selected Choice [Inflation/ CPI] | DE1: Why did the city change stormwater rates? (Check all that apply) - Selected Choice [Labor Costs] | DF1: Why did the city change stormwater rates? (Check all that apply) - Selected Choice [Other (Please Specify)] | DG1: Why did the city change stormwater rates? (Check all that apply) - Selected Choice [State/ Federal Mandate] | DH1: Why did the city change stormwater rates? (Check all that apply) - Selected Choice [Treatment Costs] | DI1: Why did the city change stormwater rates? (Check all that apply) - Other (Please Specify) - Text | DJ1: What is the rate structure for your city's stormwater service? - Selected Choice | DK1: What is the rate structure for your city's stormwater service? - Other (Please Specify) - Text | DL1: Does your city offer stormwater fee reductions or credits for onsite stormwater management? | DM1: Please describe the reduction or credit (including the amount for onsite stormwater management) | DN1: What does the average house pay for stormwater services (dollars per month)? | DO1: Does your city provide drinking water services? | DP1: What is the service population in 2024? - Service Population (Permanent Residents) - Inside City Limits | DQ1: What is the service population in 2024? - Service Population (Permanent Residents) - Outside City Limits | DR1: What is the service population in 2024? - Service Population (Including Peak Seasonal) - Inside City Limits | DS1: What is the service population in 2024? - Service Population (Including Peak Seasonal) - Outside City Limits | DT1: Please list the number of connections for the following: - Residential - Inside City Limits | DU1: Please list the number of connections for the following: - Residential - Outside City Limits | DV1: Please list the number of connections for the following: - Commercial - Inside City Limits | DW1: Please list the number of connections for the following: - Commercial - Outside City Limits | DX1: Please list the number of connections for the following: - Other - Inside City Limits | DY1: Please list the number of connections for the following: - Other - Outside City Limits | DZ1: What is the annual average water consumption for residential customers (in gallons)? | EA1: Please provide the following facility and water source information: - Total miles of water lines (all sizes), not including service laterals | EB1: Please provide the following facility and water source information: - Total number of pumps and lift stations in your city | EC1: Please provide the following facility and water source information: - How many levels or zones based on elevation do you have? | ED1: Please provide the following facility and water source information: - How far away is the water source from the city (miles)? | EE1: Please provide the following system age and capacity information: - Year of original system construction completion | EF1: Please provide the following system age and capacity information: - Year of last major update | EG1: Please provide the following system age and capacity information: - What is the capacity of your water source? | EH1: Please provide the following system age and capacity information: - What is the design capacity of your water plant(s) (MGD)? | EI1: Please provide the following system age and capacity information: - What was the average daily production in 2024 (MG)? | EJ1: Please provide the following system age and capacity information: - How much of your daily average production is sold (not including city use)? | EK1: Please provide the following system age and capacity information: - What was the peak flow of water treated in a 24-hour period in 2024 ? | EL1: Please list the amount of raw and treated water storage you have for the different types of applicable storage: - Closed Tanks - Raw Water Storage (MG) | EM1: Please list the amount of raw and treated water storage you have for the different types of applicable storage: - Closed Tanks - Treated Water Storage (MG) | EN1: Please list the amount of raw and treated water storage you have for the different types of applicable storage: - Covered Urban Reservoirs - Raw Water Storage (MG) | EO1: Please list the amount of raw and treated water storage you have for the different types of applicable storage: - Covered Urban Reservoirs - Treated Water Storage (MG) | EP1: Please list the amount of raw and treated water storage you have for the different types of applicable storage: - ASR Reservoir - Raw Water Storage (MG) | EQ1: Please list the amount of raw and treated water storage you have for the different types of applicable storage: - ASR Reservoir - Treated Water Storage (MG) | ER1: Please list the amount of raw and treated water storage you have for the different types of applicable storage: - Other (Please Specify) - Text | ES1: Please list the amount of raw and treated water storage you have for the different types of applicable storage: - Other (Please Specify) - Raw Water Storage (MG) | ET1: Please list the amount of raw and treated water storage you have for the different types of applicable storage: - Other (Please Specify) - Treated Water Storage (MG) | EU1: In what year will your daily production exceed design capacity? | EV1: Does your city have an approved water conservation and management plan? | EW1: Do you measure water loss? | EX1: What method is used to determine water loss in the system? - Selected Choice | EY1: What method is used to determine water loss in the system? - Other (Please Specify) - Text | EZ1: What percentage of the system does each type of meter represent? - Radio (%) | FA1: What percentage of the system does each type of meter represent? - Touch (%) | FB1: What percentage of the system does each type of meter represent? - Manual Read (%) | FC1: Do you have any additional comments on water services? | FD1: Does your city provide wastewater services? | FE1: What is the service population in 2024? - Service Population (Permanent Residents) - Inside City Limits | FF1: What is the service population in 2024? - Service Population (Permanent Residents) - Outside City Limits | FG1: What is the service population in 2024? - Service Population (Including Peak Seasonal) - Inside City Limits | FH1: What is the service population in 2024? - Service Population (Including Peak Seasonal) - Outside City Limits | FI1: Please list the number of connections for the following: - Residential - Inside City Limits | FJ1: Please list the number of connections for the following: - Residential - Outside City Limits | FK1: Please list the number of connections for the following: - Commercial - Inside City Limits | FL1: Please list the number of connections for the following: - Commercial - Outside City Limits | FM1: Please list the number of connections for the following: - Other - Inside City Limits | FN1: Please list the number of connections for the following: - Other - Outside City Limits | FO1: What is the annual average wastewater base (volume) for a residential customer (x1000 gal. or 1.337 CCFs)? | FP1: Please provide the following facility, lines, and treatment information: - Total miles of sewer lines (all sizes), not including service laterals | FQ1: Please provide the following facility, lines, and treatment information: - Total number of pumps and lift stations in your city | FR1: Please provide the following facility, lines, and treatment information: - Total number of treatment plants | FS1: Please provide the following facility, lines, and treatment information: - What percent of city wastewater lines also serve stormwater (i.e. combined sewer)? | FT1: What level of wastewater treatment is provided to city wastewater (Check all that apply)? - Selected Choice [Advanced Treatment/ Tertiary] | FU1: What level of wastewater treatment is provided to city wastewater (Check all that apply)? - Selected Choice [Nitrogen Removal] | FV1: What level of wastewater treatment is provided to city wastewater (Check all that apply)? - Selected Choice [Other (Please Specify)] | FW1: What level of wastewater treatment is provided to city wastewater (Check all that apply)? - Selected Choice [Phosphorous Removal] | FX1: What level of wastewater treatment is provided to city wastewater (Check all that apply)? - Selected Choice [Primary] | FY1: What level of wastewater treatment is provided to city wastewater (Check all that apply)? - Selected Choice [Secondary] | FZ1: What level of wastewater treatment is provided to city wastewater (Check all that apply)? - Other (Please Specify) - Text | GA1: Please provide the following system age and capacity information: - Year of original plant construction completion | GB1: Please provide the following system age and capacity information: - Year of last major plant update | GC1: Please provide the following system age and capacity information: - What is the design capacity of your treatment plant(s) in dry weather (MGD)? | GD1: Please provide the following system age and capacity information: - What is the design capacity of your treatment plant(s) in peak wet weather (MGD)? | GE1: Please provide the following system age and capacity information: - What is the total amount of wastewater treated in 2024 (MG)? | GF1: Please provide the following system age and capacity information: - What was the peak wet weather flow in 2024 (MGD)? | GG1: Please provide the following system age and capacity information: - What was the peak dry weather flow in 2024 (MGD)? | GH1: At what percent (%) capacity is the entire wastewater system operating? | GI1: In what year will the wastewater system be at maximum capacity? | GJ1: In what year will your daily production exceed design capacity? | GK1: Does your city administer an industrial wastewater pre-treatment program? | GL1: Does your city apply or provide reclaimed water to public/private property? | GM1: What percentage (%) of total reclaimed water is reused/applied? | GN1: Where does this reuse and application occur (i.e. city park, private golf course, industrial cooling tower, etc.)? | GO1: Does your city apply biosolids to public/ private property? | GP1: Where does this biosolid application occur (i.e. city park, private golf course, etc.)? | GQ1: Does your city landfill biosolids? | GR1: What percentage (%) of biosolids are landfilled? | GS1: Do you have any additional comments on wastewater services? | GT1: Does your city provide stormwater services? | GU1: Please list the number of accounts for the following: - Residential - Inside City Limits | GV1: Please list the number of accounts for the following: - Residential - Outside City Limits | GW1: Please list the number of accounts for the following: - Commercial - Inside City Limits | GX1: Please list the number of accounts for the following: - Commercial - Outside City Limits | GY1: Please list the number of accounts for the following: - Other - Inside City Limits | GZ1: Please list the number of accounts for the following: - Other - Outside City Limits | HA1: Please provide the following facility and water source information: - Total miles of piped system | HB1: Please provide the following facility and water source information: - Total miles of open channels, ditches, and swales | HC1: What is the average Equivalent Dwelling Unit (EDU) for residential in square feet? | HD1: Do you have any additional comments on stormwater services? | HE1: Thank You for participating in this survey. Do you have any additional comments on any topic in this survey?
A2: Heppner | B2: 1205 | C2: 2 | D2: 11 | E2: 1 | G2: 1 | H2: 1 | I2: 1 | J2: 0 | K2: 1 | L2: 0 | M2: 2 | N2: 1 | O2: 1 | P2: 1 | Q2: 0 | R2: 1 | S2: 0 | U2: 5 | W2: 30 | Z2: 60 | AA2: 151 | AB2: 90 | AC2: 1 | AD2: We have an internal fund that pays for discounts for "yard of the month," winners. We have a internal account that contains funds donated for hardship requests. These requests for payment must be heard by our Utilities Committee or Council. The usage of utilities donation funds is not at the discretion of employees. | AE2: 3 | AF2: 2 | AH2: The adjustment for leaks are only made if due to City error. Customer error or damage to customer side of supply is the responsibility of the customer. | AP2: 1 | AQ2: 1 | AR2: 2 | AY2: 1 | AZ2: 4 | BB2: No continued charges if meter is locked and no account is open. | BC2: 1 | BD2: 1 | BE2: 0 | BF2: 1 | BG2: 1 | BH2: 1 | BI2: Deposit for new accounts | BJ2: 2 | BK2: 0 | BL2: 0 | BM2: 1 | BN2: 0 | BO2: 0 | BP2: 0 | BQ2: 0 | BR2: none | BS2: 1 | BT2: 1 | BV2: 1 | BW2: 2025 | BX2: 1 | BY2: 3.2 | BZ2: 0 | CA2: 1 | CB2: 1 | CC2: 1 | CD2: 0 | CE2: 1 | CF2: We use CPI Water/Wastewater to adjust rate | CG2: 1 | CI2: 53.17 | CJ2: 1 | CK2: 2025 | CL2: 1 | CM2: 3.2 | CN2: 0 | CO2: 1 | CP2: 1 | CQ2: 0 | CR2: 0 | CS2: 1 | CU2: 1 | CW2: 50.69 | CX2: 2 | DO2: 1 | DP2: 1200 | DQ2: 100 | DR2: 1200 | DS2: 100 | EM2: 1.35 | EV2: 1 | EW2: 1 | EX2: 2 | EZ2: 40 | FA2: 50 | FB2: 10 | FD2: 1 | GO2: 1 | GP2: Private farmland | GQ2: 2 | GT2: 2
A3: Spray | B3: 141 | C3: 1 | D3: 9 | E3: 1 | G3: 1 | H3: 1 | I3: 0 | J3: 1 | K3: 1 | L3: 1 | M3: 2 | N3: 0 | O3: 0 | P3: 1 | Q3: 0 | R3: 0 | S3: 0 | U3: 10 | W3: 1 | AC3: 1 | AD3: If customer has fallen on hard times, the council will waive a month or if there is a water leak that is not the property owners fault | AE3: 3 | AF3: 2 | AG3: 30 | AM3: 1 | AN3: 1 | AO3: 1 | AY3: 1 | AZ3: 4 | BB3: Still pay monthly rate unless ask for water to be turned off | BC3: 0 | BD3: 1 | BE3: 0 | BF3: 0 | BG3: 1 | BH3: 0 | BJ3: 2 | BK3: 0 | BL3: 0 | BM3: 1 | BN3: 0 | BO3: 0 | BP3: 0 | BQ3: 0 | BR3: none | BV3: 1 | BW3: 2019 | BX3: 1 | BY3: 0.03 | BZ3: 0 | CA3: 1 | CB3: 1 | CC3: 0 | CD3: 0 | CE3: 1 | CG3: 1 | CJ3: 1 | CK3: 2019 | CL3: 1 | CM3: 0.04 | CN3: 0 | CO3: 1 | CP3: 1 | CQ3: 0 | CR3: 0 | CS3: 1 | CU3: 1 | CX3: 2 | DO3: 1 | DP3: 114 | DR3: 124 | DT3: 114 | DV3: 10 | EB3: 1 | ED3: 0.25 | EV3: 1 | EW3: 1 | EX3: 2 | FD3: 1 | FE3: 114 | FG3: 124 | FI3: 114 | FK3: 10 | FQ3: 1 | GA3: 2009 | GK3: 2 | GL3: 2 | GO3: 2 | GQ3: 2 | GT3: 2
A4: Canyon City | B4: 675 | C4: 2 | D4: 12 | E4: 1 | G4: 1 | H4: 1 | I4: 1 | J4: 0 | K4: 0 | L4: 1 | M4: 2 | N4: 0 | O4: 1 | P4: 0 | Q4: 1 | R4: 0 | S4: 0 | V4: 0.01 | X4: 5 | Z4: 30 | AC4: 2 | AE4: 3 | AF4: 2 | AG4: 30 | AM4: 1 | AN4: 1 | AP4: 2 | AQ4: 2 | AY4: 2 | AZ4: 2 | BC4: 1 | BD4: 0 | BE4: 0 | BF4: 0 | BG4: 1 | BH4: 1 | BJ4: 2 | BS4: 2 | BT4: 2 | BU4: 2 | BV4: 1 | BW4: 2024 | BX4: 1 | BY4: 0.02 | BZ4: 1 | CA4: 0 | CB4: 0 | CC4: 0 | CD4: 0 | CE4: 0 | CG4: 1 | CI4: 50.25 | CJ4: 1 | CK4: 2025 | CL4: 1 | CM4: 30 | CN4: 1 | CO4: 0 | CP4: 0 | CQ4: 0 | CR4: 0 | CS4: 0 | CU4: 1 | CW4: 77 | CX4: 2 | DO4: 1 | DP4: 668 | DQ4: 30 | DR4: 668 | DS4: 30 | DT4: 312 | DU4: 5 | DV4: 32 | DW4: 1 | DZ4: 12123 | EV4: 2 | EW4: 2 | FB4: 100 | FC4: currently working on a major water project | FD4: 1 | FE4: 668 | FF4: 6 | FG4: 668 | FH4: 6 | FI4: 312 | FK4: 32 | GO4: 2 | GQ4: 2 | GS4: Our wastewater plant is in a John Day about a mile out of town. | GT4: 2
A5: Nehalem | B5: 299 | C5: 1 | D5: 1 | E5: 1 | G5: 1 | H5: 1 | I5: 1 | J5: 0 | K5: 0 | L5: 0 | M5: 1 | N5: 0 | O5: 1 | P5: 1 | Q5: 0 | R5: 0 | S5: 0 | U5: 10 | W5: 20 | Z5: 90 | AC5: 2 | AE5: 3 | AF5: 2 | AH5: They are allowed up to 50% of an overage 2 times a year | AJ5: 15 | AN5: 1 | AO5: 1 | AP5: 2 | AS5: 2023 | AT5: n/a | AU5: n/a | AV5: 2024 | AW5: n/a | AX5: n/a | AY5: 2 | AZ5: 4 | BB5: if the onwer is hooked up to the system they are still charge the monthly base rate. | BC5: 0 | BD5: 1 | BE5: 0 | BF5: 0 | BG5: 1 | BH5: 1 | BJ5: 2 | BS5: 2 | BV5: 2 | CJ5: 2 | CX5: 2 | DO5: 1 | DP5: 264 | DQ5: 636 | DT5: 264 | DU5: 636 | DZ5: 36850000 | EF5: 2024 | EV5: 1 | EW5: 1 | EX5: 1 | FD5: 2 | GT5: 2
A6: Gates | B6: 573 | C6: 2 | D6: 3 | E6: 1 | G6: 1 | H6: 1 | I6: 0 | J6: 0 | K6: 1 | L6: 0 | M6: 2 | N6: 0 | O6: 1 | P6: 1 | Q6: 0 | R6: 1 | S6: 0 | U6: 5 | Z6: 72 | AC6: 2 | AE6: 3 | AF6: 2 | AG6: 3 | AN6: 1 | AO6: 1 | AP6: 2 | AS6: 2012 | AT6: NA | AU6: NA | AW6: NA | AX6: NA | AY6: 2 | AZ6: 2 | BC6: 0 | BD6: 0 | BE6: 0 | BF6: 1 | BG6: 1 | BH6: 0 | BI6: NSF if needed | BJ6: 2 | BK6: 0 | BL6: 0 | BM6: 1 | BN6: 0 | BO6: 0 | BP6: 0 | BQ6: 0 | BR6: Street Fee | BS6: 2 | BV6: 1 | BW6: 2025 | BX6: 1 | BY6: 0.03 | BZ6: 1 | CA6: 1 | CB6: 1 | CC6: 0 | CD6: 0 | CE6: 1 | CG6: 5 | CH6: Monthly Base Rate (includes 1,000 gl plus $4.00 per 1,000 gls | CI6: 83.43 | CJ6: 2 | CX6: 2 | DO6: 1 | DP6: 500 | DT6: 195 | DU6: 18 | DV6: 4 | DX6: 1 | DZ6: 48000 | EA6: 7 | EB6: 3 | EC6: 2 | ED6: 0 | EE6: 1950 | EF6: 2012 | EH6: 0.3 | EI6: 0.15 | EK6: 210 | EM6: 500000 | EU6: ? | EV6: 1 | EW6: 1 | EX6: 1 | EZ6: 0.98 | FA6: 0.02 | FD6: 2 | GT6: 2
A7: Glendale | B7: 859 | C7: 2 | D7: 7 | E7: 1 | G7: 1 | H7: 1 | I7: 1 | J7: 0 | K7: 1 | L7: 0 | M7: 2 | N7: 1 | O7: 1 | P7: 1 | Q7: 0 | R7: 0 | S7: 0 | U7: 20 | AB7: 30 | AC7: 2 | AE7: 2 | AP7: 1 | AQ7: 1 | AY7: 2 | AZ7: 2 | BJ7: 2 | BS7: 1 | BT7: 1 | BV7: 1 | BW7: 2025 | BX7: 1 | BY7: 3.2 | BZ7: 0 | CA7: 1 | CB7: 1 | CC7: 0 | CD7: 0 | CE7: 1 | CG7: 3 | CI7: 57.25 | CJ7: 1 | CK7: 2025 | CL7: 1 | CM7: 3.2 | CN7: 1 | CO7: 1 | CP7: 1 | CQ7: 0 | CR7: 0 | CS7: 1 | CU7: 1 | CW7: 86 | CX7: 2 | DO7: 1 | DP7: 875 | DR7: 875 | DT7: 350 | DU7: 37 | DV7: 32 | DZ7: 4000 | EB7: 2 | ED7: 0.25 | EE7: 1970 | EF7: 1998 | EG7: 1000000 | EJ7: 70000 | EW7: 1 | EX7: 3 | FB7: 100 | FD7: 1 | FE7: 875 | FG7: 875 | FI7: 350 | FJ7: 7 | FK7: 33 | FL7: 4 | FT7: 0 | FU7: 1 | FV7: 0 | FW7: 1 | FX7: 1 | FY7: 1 | GA7: 1950 | GB7: 2021 | GL7: 2 | GO7: 1 | GP7: private ranch | GQ7: 2 | GT7: 2
A8: Joseph | B8: 1182 | C8: 2 | D8: 11 | E8: 1 | G8: 1 | H8: 1 | I8: 1 | J8: 0 | K8: 1 | L8: 1 | M8: 1 | N8: 0 | O8: 1 | P8: 1 | Q8: 0 | R8: 1 | S8: 0 | U8: 10 | W8: 10 | Z8: 25 | AC8: 2 | AE8: 3 | AH8: as long as the user has been actively working to fix the leak | AJ8: 100 | AK8: 100 | AO8: 1 | AP8: 1 | AQ8: 2 | AT8: unknown | AU8: n/a | AV8: 2024 | AW8: 2023 | AX8: n/a | AY8: 2 | AZ8: 4 | BB8: Water services are discontinued, sewer services continue to be charged. | BC8: 0 | BD8: 0 | BE8: 0 | BF8: 0 | BG8: 1 | BH8: 0 | BJ8: 2 | BK8: 0 | BL8: 0 | BM8: 0 | BN8: 0 | BO8: 0 | BP8: 1 | BQ8: 0 | BS8: 2 | BT8: 2 | BV8: 1 | BW8: 2025 | BX8: 1 | BY8: 61.5 | BZ8: 0 | CA8: 1 | CB8: 0 | CC8: 1 | CD8: 0 | CE8: 1 | CF8: Water Project to upgrade infrastructure | CG8: 1 | CI8: 53 | CJ8: 1 | CK8: 2023 | CL8: 1 | CM8: 64 | CN8: 0 | CO8: 1 | CP8: 0 | CQ8: 1 | CR8: 0 | CS8: 0 | CT8: DEQ required update costs | CU8: 1 | CW8: 43.24 | CX8: 2 | DO8: 1 | DZ8: 144000000 | ED8: 1 | EF8: 2025 | EL8: 9 | EN8: 7 | EO8: 12 | EP8: 9 | EQ8: 8 | EU8: unknown | EV8: 1 | EW8: 1 | EX8: 1 | EZ8: 98 | FA8: 2 | FD8: 1 | GO8: 1 | GP8: Local ranch | GQ8: 2 | GS8: no | GT8: 2
A9: Ashland | B9: 21862 | C9: 5 | D9: 7 | E9: 1 | G9: 1 | H9: 1 | I9: 1 | J9: 0 | K9: 1 | L9: 1 | M9: 1 | N9: 1 | O9: 1 | P9: 0 | Q9: 0 | R9: 0 | S9: 0 | Z9: 45 | AA9: 50 | AB9: 30 | AC9: 1 | AD9: Low income discount of 30% if customer is at or below 200% Federal Poverty Level up to $400. | AE9: 3 | AF9: 3 | AH9: 18 months | AI9: We would look at the same time period the previous year, and give the customer up to 50% credit compared to that time period. If they are a commercial user, we would also decrease their sewer charge accordingly. | AJ9: 7 | AK9: 3 | AL9: 2 | AP9: 1 | AQ9: 1 | AR9: 1 | AS9: 2024 | AT9: 2022 | AU9: 2020 | AV9: 2012 | AW9: 2019 | AX9: 2020 | AY9: 2 | AZ9: 2 | BC9: 0 | BD9: 1 | BE9: 0 | BF9: 0 | BG9: 0 | BH9: 0 | BJ9: 1 | BK9: 1 | BL9: 0 | BM9: 0 | BN9: 1 | BO9: 1 | BP9: 1 | BQ9: 1 | BS9: 2 | BT9: 2 | BU9: 2 | BV9: 1 | BW9: 2025 | BZ9: 1 | CA9: 1 | CB9: 1 | CC9: 1 | CD9: 0 | CE9: 1 | CF9: The rates were increased not by a flat percentage, but looked at each rate class and appropriate charge. We also changed the tier structure. | CG9: 1 | CI9: 58.17 | CJ9: 1 | CK9: 2019 | CL9: 1 | CM9: 4 | CN9: 1 | CO9: 1 | CP9: 1 | CQ9: 0 | CR9: 0 | CS9: 1 | CU9: 4 | CV9: Winter average+flat | CW9: 47.52 | CX9: 1 | CY9: 5 | CZ9: 1 | DA9: 8 | DB9: 1 | DC9: 1 | DD9: 1 | DE9: 1 | DF9: 0 | DG9: 0 | DH9: 1 | DJ9: 1 | DL9: 1 | DN9: 5.43 | DO9: 1 | DP9: 23000 | DT9: 7144 | DU9: 42 | DV9: 763 | DW9: 9 | DX9: 233 | DZ9: 37000 | EA9: 120 | EB9: 3 | EC9: 14 | ED9: 2 | EE9: 1948 | EF9: 1994 | EG9: 800 | EH9: 7.5 | EI9: 2.96 | EJ9: 1 | EK9: 5.7 | EM9: 6.8 | EP9: 2 | EU9: na | EV9: 1 | EW9: 1 | EX9: 1 | EZ9: 0.05 | FB9: 0.95 | FD9: 1 | FE9: 23000 | FI9: 8196 | FJ9: 10 | FK9: 686 | FL9: 5 | FM9: 79 | FN9: 3 | FO9: 2.7 | FP9: 112 | FQ9: 7 | FR9: 2 | FS9: 3 | FT9: 1 | FU9: 0 | FV9: 0 | FW9: 0 | FX9: 0 | FY9: 0 | GA9: 1936 | GB9: 2002 | GC9: 2.4 | GD9: 3.6 | GE9: 800 | GF9: 10.5 | GG9: 2.3 | GH9: 50 | GI9: NA | GJ9: NA | GK9: 1 | GL9: 2 | GM9: 0% | GO9: 2 | GQ9: 1 | GR9: 1 | GT9: 1 | GU9: 7601 | GV9: 6 | GW9: 690 | GY9: 79 | HB9: NA
A10: Irrigon | B10: 2372 | C10: 3 | D10: 11 | E10: 1 | G10: 1 | H10: 1 | I10: 1 | J10: 0 | K10: 1 | L10: 0 | M10: 1 | N10: 0 | O10: 1 | P10: 1 | Q10: 0 | R10: 1 | S10: 0 | U10: 5 | W10: 30 | Z10: 10 | AC10: 2 | AE10: 2 | AG10: 30 | AJ10: 3 | AK10: 4 | AL10: 0 | AP10: 2 | AQ10: 2 | AS10: 2006 | AT10: 2006 | AU10: N/A | AV10: 2006 | AW10: 2006 | AX10: N/A | AY10: 2 | AZ10: 4 | BB10: Revenue Bonds stay static | BC10: 0 | BD10: 0 | BE10: 0 | BF10: 0 | BG10: 1 | BH10: 0 | BJ10: 2 | BK10: 0 | BL10: 0 | BM10: 0 | BN10: 0 | BO10: 1 | BP10: 1 | BQ10: 0 | BS10: 2 | BT10: 2 | BV10: 1 | BX10: 1 | BY10: 2.3 | BZ10: 1 | CA10: 1 | CB10: 1 | CC10: 0 | CD10: 0 | CE10: 0 | CG10: 1 | CJ10: 1 | CL10: 1 | CM10: 2.3 | CN10: 1 | CO10: 1 | CP10: 1 | CQ10: 0 | CR10: 0 | CS10: 1 | CU10: 1 | CW10: 50.82 | CX10: 2 | DO10: 1 | DP10: 2000 | DQ10: 60 | DR10: 2000 | DS10: 60 | DT10: 740 | DU10: 40 | DV10: 25 | DW10: 1 | DX10: 0 | DY10: 1 | DZ10: 90000 | EA10: 22 | EB10: 2 | EC10: 1 | ED10: 2 | EE10: 1965 | EF10: 2024 | EH10: 5 | EI10: 1 | EJ10: 0.99 | EK10: 1 | EL10: 1 | EM10: 1.5 | EN10: 1 | EO10: 1 | EP10: 1 | EQ10: 1 | EU10: Unknown | EV10: 2 | EW10: 1 | EX10: 1 | EZ10: 0.98 | FA10: 0 | FB10: 2 | FC10: N/A | FD10: 1 | FE10: 2000 | FF10: 40 | FG10: 2000 | FH10: 40 | FI10: 740 | FJ10: 9 | FK10: 25 | FL10: 6 | FO10: 18000 | FP10: 13 | FQ10: 10 | FR10: 2 | FS10: 2 | FT10: 0 | FU10: 1 | FV10: 0 | FW10: 0 | FX10: 1 | FY10: 1 | GA10: 2017 | GB10: 2013 | GH10: 50 | GI10: 2035 est | GJ10: 2035 est | GK10: 2 | GL10: 2 | GO10: 2 | GQ10: 2 | GS10: None | GT10: 2 | HE10: Got to Love surveys. So how much can we get?
A11: Long Creek | B11: 173 | C11: 1 | D11: 12 | E11: 1 | G11: 1 | H11: 1 | I11: 1 | J11: 0 | K11: 1 | L11: 0 | M11: 2 | N11: 0 | O11: 1 | P11: 1 | Q11: 0 | R11: 1 | S11: 0 | U11: 10 | W11: 30 | Z11: 60 | AC11: 1 | AD11: Hardship cases are dealt with individually. | AE11: 3 | AF11: 2 | AH11: only for overage charges | AJ11: 0 | AK11: 0 | AL11: 0 | AM11: 1 | AN11: 1 | AO11: 1 | AT11: 2024-2025 | AU11: NA | AW11: NA | AX11: NA | AY11: 2 | AZ11: 2 | BC11: 0 | BD11: 0 | BE11: 1 | BF11: 0 | BG11: 0 | BH11: 0 | BJ11: 2 | BK11: 0 | BL11: 0 | BM11: 1 | BN11: 0 | BO11: 0 | BP11: 0 | BQ11: 0 | BR11: NA | BV11: 1 | BW11: 2025 | BX11: 1 | BY11: 0.035 | BZ11: 0 | CA11: 1 | CB11: 0 | CC11: 1 | CD11: 0 | CE11: 0 | CF11: OVERALL COST INCREASES | CG11: 2 | CI11: 29 | CJ11: 1 | CK11: 2025 | CL11: 1 | CM11: 0.035 | CN11: 0 | CO11: 1 | CP11: 0 | CQ11: 0 | CR11: 0 | CS11: 0 | CU11: 1 | CW11: 26 | CX11: 2 | DO11: 1 | DP11: 175 | DQ11: 0 | DT11: 97 | DV11: 7 | DX11: 5 | DZ11: 1000000 | EB11: 0 | EC11: 1 | EN11: 2 | EU11: undetermined | FD11: 1 | FE11: 175 | GO11: 2 | GQ11: 2 | GT11: 2
A12: Columbia City | B12: 1946 | C12: 3 | D12: 1 | E12: 1 | G12: 1 | H12: 1 | I12: 1 | J12: 1 | K12: 1 | L12: 1 | M12: 1 | N12: 1 | O12: 1 | P12: 1 | Q12: 0 | R12: 1 | S12: 0 | W12: 15 | Z12: 30 | AB12: 60 | AC12: 2 | AE12: 3 | AF12: 3 | AH12: eligible for 2 months leak credit if fixed in a timely manner and the adj is a percentage of what the leak amount is calculated at | AI12: Wastewater leak credits are not done for the months of June - September because only a flat rate is charged during the summer months. October - May the leak credit is calculated for up to 2 months if done in a timely manner and is a percentage of what the leak amount is calculated at | AT12: unk | AW12: unk | AY12: 2 | AZ12: 4 | BB12: Close account with no charges until opened by next occupant unless the property owner requests to have water left on in their name | BC12: 0 | BD12: 0 | BE12: 0 | BF12: 0 | BG12: 1 | BH12: 0 | BJ12: 2 | BS12: 2 | BT12: 2 | BV12: 1 | BW12: 2025 | BX12: 1 | BY12: 15 | BZ12: 1 | CA12: 0 | CB12: 1 | CC12: 0 | CD12: 0 | CE12: 1 | CG12: 1 | CI12: 67.94 | CJ12: 1 | CK12: 2025 | CL12: 1 | CM12: 5 | CN12: 1 | CO12: 0 | CP12: 1 | CQ12: 0 | CR12: 0 | CS12: 1 | CU12: 4 | CV12: Flat rate + water used | CW12: 56.78 | CX12: 2 | DO12: 1 | DP12: 1946 | DT12: 827 | DU12: 9 | DV12: 19 | DX12: 15 | EA12: 13.7 | EB12: 8 | EC12: 5 | ED12: 0 | EE12: 1936 | EF12: 2019 | EG12: 216000 | EH12: 0.72 | EM12: 1.4 | EU12: never | EV12: 1 | EW12: 1 | EX12: 1 | EZ12: 100 | FD12: 1 | FE12: 1946 | FP12: 17.7 | FQ12: 12 | FR12: 1 | FS12: 2 | FT12: 0 | FU12: 0 | FV12: 1 | FW12: 0 | FX12: 0 | FY12: 0 | FZ12: All wastewater is pumped to St Helens to be treated | GO12: 2 | GQ12: 2 | GT12: 2
A13: Seaside | B13: 7268 | C13: 4 | D13: 1 | E13: 2 | G13: 1 | H13: 1 | I13: 1 | J13: 1 | K13: 0 | L13: 1 | M13: 1 | N13: 0 | O13: 1 | P13: 1 | Q13: 0 | R13: 1 | S13: 0 | U13: 0.1 | W13: 40 | Z13: 86 | AC13: 1 | AD13: We provide a discount for repaired water leaks. Billing errors are handled on a case by case basis. | AE13: 3 | AF13: 3 | AH13: To the demonstrated start of the leak (based on usage), as long as repair is done in a reasonable amount of time. | AI13: We offer a one time reduction for repaired leaks. If approved then the City will waive half of the leak amount above a customer's average bill. | AJ13: 33.3 | AK13: 18.5 | AO13: 1 | AP13: 1 | AQ13: 1 | AT13: Unknown | AU13: N/A | AW13: Unknown | AX13: N/A | AY13: 1 | AZ13: 4 | BB13: Charges continue and are the responsibility of the homeowner | BC13: 0 | BD13: 0 | BE13: 0 | BF13: 0 | BG13: 1 | BH13: 1 | BJ13: 2 | BS13: 2 | BT13: 2 | BV13: 2 | CJ13: 1 | CK13: 2025 | CL13: 1 | CM13: 4.1 | CN13: 1 | CO13: 1 | CP13: 1 | CQ13: 0 | CR13: 0 | CS13: 1 | CU13: 4 | CV13: Flat rate for residential, flat rate plus usage for commercial | CW13: 77.29 | CX13: 2 | DO13: 2 | FD13: 1 | FE13: 7500 | FF13: 1000 | FG13: 35000 | FH13: 1500 | FI13: 2964 | FJ13: 8 | FK13: 710 | FO13: 3920445 | FQ13: 26 | FR13: 6 | FS13: 8 | FT13: 0 | FU13: 0 | FV13: 0 | FW13: 0 | FX13: 1 | FY13: 0 | GA13: 1986 | GB13: 2001 | GC13: 2.25 | GD13: 6.75 | GE13: 1095 | GF13: 4 | GG13: 4 | GI13: Unknown | GJ13: Unknown | GK13: 2 | GL13: 2 | GM13: 0% | GO13: 1 | GP13: Given to local and City-owned farms | GQ13: 2 | GT13: 2
A14: Wheeler | B14: 428 | C14: 1 | D14: 1 | E14: 2 | G14: 1 | H14: 1 | I14: 0 | J14: 0 | K14: 0 | L14: 0 | M14: 2 | N14: 0 | O14: 1 | P14: 1 | Q14: 1 | R14: 1 | S14: 1 | T14: Liens are only issued in severe cases - We've never had to use this method before but our code allows it | U14: 0.015 | V14: 0.015 | W14: 0 | Y14: 0.015 | Z14: 105 | AC14: 1 | AD14: If a customer can show hardship, the City Manager has the authority to grant exceptions to the rule - but this must include the creation of a repayment plan that is feasible for both the City and the water customer. | AE14: 3 | AF14: 2 | AJ14: 0.075 | AN14: 1 | AO14: 1 | AP14: 1 | AR14: 1 | AS14: 2023 | AT14: NA | AU14: 2012 | AV14: 2023 | AW14: NA | AX14: 2012 | AY14: 2 | AZ14: 3 | BC14: 0 | BD14: 0 | BE14: 0 | BF14: 0 | BG14: 1 | BH14: 0 | BJ14: 1 | BK14: 0 | BL14: 0 | BM14: 1 | BN14: 0 | BO14: 0 | BP14: 0 | BQ14: 0 | BR14: Traffic & Safety | BS14: 2 | BU14: 2 | BV14: 2 | CJ14: 2 | CX14: 1 | CY14: 3 | CZ14: 1 | DA14: 0.4 | DB14: 3 | DC14: 0 | DD14: 1 | DE14: 0 | DF14: 0 | DG14: 0 | DH14: 0 | DJ14: 1 | DL14: 2 | DN14: 5 | DO14: 1 | DP14: 259 | DQ14: 0 | DR14: 259 | DS14: 0 | DT14: 223 | DU14: 0 | DV14: 30 | DW14: 1 | DX14: 6 | DY14: 1 | DZ14: 62517 | EA14: 4 | EB14: 2 | EC14: 1 | ED14: 2 | EF14: 2016 | EJ14: 0.61 | EL14: 1 | EM14: 52 | EN14: 1 | EO14: 1 | EP14: 1 | EQ14: 1 | EU14: 2050ish | EV14: 2 | EW14: 1 | EX14: 1 | EZ14: 100 | FD14: 2 | GT14: 1 | GU14: 223 | GV14: 1 | GW14: 30 | GX14: 1 | GY14: 6 | GZ14: 1 | HA14: 4
A15: Fairview | B15: 10473 | C15: 4 | D15: 2 | E15: 4 | F15: WATER AND SEWER ARE MONTHLY. SEWER ONLY IS BI-MONTHLY | G15: 0 | H15: 1 | I15: 1 | J15: 1 | K15: 1 | L15: 1 | M15: 2 | N15: 1 | O15: 1 | P15: 1 | Q15: 0 | R15: 1 | S15: 0 | U15: 0.05 | W15: 10 | Z15: 10 | AC15: 1 | AD15: SNOWBIRD IS 35% DISCOUNT FOR SEWER | AE15: 3 | AF15: 2 | AP15: 2 | AQ15: 2 | AR15: 2 | AS15: 2021 | AT15: 2021 | AU15: 2021 | AV15: 2025 | AW15: 2025 | AX15: 2025 | AY15: 1 | BC15: 0 | BD15: 0 | BE15: 0 | BF15: 0 | BG15: 1 | BH15: 1 | BJ15: 1 | BK15: 1 | BL15: 0 | BM15: 1 | BN15: 0 | BO15: 1 | BP15: 0 | BQ15: 0 | BR15: CAPITAL IMPROVEMENT | BS15: 2 | BT15: 2 | BU15: 2 | BV15: 1 | BW15: 2025 | BX15: 1 | BY15: 8 | BZ15: 0 | CA15: 1 | CB15: 0 | CC15: 0 | CD15: 0 | CE15: 0 | CG15: 1 | CI15: 36.19 | CJ15: 1 | CK15: 2025 | CL15: 1 | CM15: 8 | CN15: 0 | CO15: 1 | CP15: 0 | CQ15: 0 | CR15: 0 | CS15: 0 | CU15: 1 | CW15: 37.36 | CX15: 1 | CY15: 7 | CZ15: 1 | DA15: 8 | DB15: 3 | DC15: 0 | DD15: 1 | DE15: 0 | DF15: 0 | DG15: 0 | DH15: 0 | DJ15: 1 | DL15: 1 | DM15: CAN PETITION FOR REDUCTION | DN15: 13.29 | DO15: 1 | FD15: 1 | GO15: 2 | GT15: 1
A16: Bay City | B16: 1598 | C16: 3 | D16: 1 | E16: 1 | G16: 1 | H16: 1 | I16: 1 | J16: 1 | K16: 1 | L16: 1 | M16: 1 | N16: 0 | O16: 1 | P16: 1 | Q16: 0 | R16: 1 | S16: 0 | U16: 0.1 | W16: 2 | Z16: 90 | AC16: 1 | AD16: Summer irrigation waiver of sewer fees; leak credit for sewer fee and 50% of water charge; option to suspend service for vacation time | AE16: 3 | AF16: 3 | AG16: 60 | AI16: In the case of leaks or summer irrigation, we waive the additional consumption (over the base amount, or the average winter consumption volume). | AO16: 1 | AP16: 2 | AQ16: 2 | AS16: 2024 | AT16: 2010 | AU16: never | AV16: 2024 | AW16: 2024 | AX16: N/A | AY16: 2 | AZ16: 4 | BB16: We do not charge water or sewer, but charge Street Maintenance Fee | BC16: 0 | BD16: 1 | BE16: 0 | BF16: 0 | BG16: 1 | BH16: 0 | BJ16: 2 | BK16: 0 | BL16: 0 | BM16: 0 | BN16: 0 | BO16: 0 | BP16: 1 | BQ16: 0 | BS16: 1 | BT16: 1 | BV16: 1 | BW16: 2025 | BX16: 1 | BY16: 30 | BZ16: 1 | CA16: 1 | CB16: 1 | CC16: 0 | CD16: 0 | CE16: 1 | CG16: 1 | CI16: 56 | CJ16: 1 | CK16: 2025 | CL16: 1 | CM16: 3 | CN16: 0 | CO16: 1 | CP16: 0 | CQ16: 0 | CR16: 0 | CS16: 0 | CU16: 4 | CV16: Water consumption | CW16: 54.57 | CX16: 2 | DO16: 1 | DP16: 1600 | DQ16: 60 | DT16: 800 | DU16: 50 | DV16: 4 | DW16: 2 | DZ16: 55000 | EA16: 8 | EB16: 1 | EC16: 2 | ED16: 8 | EE16: 1981 | EF16: 2024 | EG16: 500000000 | EH16: 2.2 | EI16: 0.8 | EJ16: 0.67 | EK16: 1.1 | EM16: 1.3 | EU16: 2050 | EV16: 1 | EW16: 1 | EX16: 1 | EZ16: 95 | FB16: 5 | FD16: 1 | FE16: 1650 | FI16: 823 | FK16: 4 | FO16: 55000 | FP16: 8 | FQ16: 2 | FR16: 2 | FS16: 2 | FT16: 0 | FU16: 0 | FV16: 0 | FW16: 0 | FX16: 1 | FY16: 0 | GA16: 1983 | GB16: 2023 | GC16: 1.4 | GD16: 1.4 | GE16: 90 | GF16: 1.4 | GG16: 0.4 | GH16: 65 | GI16: 2040 | GJ16: 2040 | GK16: 1 | GL16: 2 | GO16: 2 | GQ16: 2 | GT16: 2
A17: Millersburg | B17: 3214 | C17: 3 | D17: 4 | E17: 2 | G17: 1 | H17: 1 | I17: 1 | J17: 0 | K17: 0 | L17: 0 | M17: 1 | N17: 1 | O17: 1 | P17: 0 | Q17: 1 | R17: 0 | S17: 0 | U17: 0 | V17: 0.09 | X17: 0 | Y17: 0.09 | Z17: 49 | AC17: 2 | AE17: 3 | AF17: 3 | AH17: Customer can get credit for one billing cycle (approx. 60 days). There is not a specific | AI17: Where a water leak exists underground between the meter and the building during the monitoring period for wastewater flow charges, the utility may allow for an adjustment on the wastewater variable charges. In order to qualify for a credit, the leak must be large enough to cause the total consumption to be greater than one and one-half the average amount that has been previously charged to the premises, and the leak must be repaired within 30 days after the customer has been notified of such leak. For most customers, the variable charges will be adjusted to reflect past winter water consumption records for the property. For customers that are billed based on actual monthly water consumption, the variable charges will be calculated using an estimate of consumption based either upon the customer's prior use during the same season of the year or upon a reasonable comparison with the use of other customers receiving the same class of service during the same period and under similar circumstances and conditions. Where past water consumption records are not available, the variable charges will be adjusted to reflect the average water consumption for similar accounts. | AK17: 25 | AM17: 1 | AO17: 1 | AP17: 1 | AQ17: 1 | AR17: 1 | AS17: 2021 | AT17: 2021 | AU17: n/a | AV17: 2020 | AW17: 2020 | AX17: 2020 | AY17: 1 | AZ17: 2 | BC17: 0 | BD17: 1 | BE17: 0 | BF17: 0 | BG17: 0 | BH17: 0 | BJ17: 2 | BK17: 0 | BL17: 0 | BM17: 1 | BN17: 0 | BO17: 0 | BP17: 0 | BQ17: 0 | BR17: none | BS17: 2 | BT17: 2 | BV17: 1 | BW17: 2025 | BX17: 1 | BY17: 0.03 | BZ17: 0 | CA17: 0 | CB17: 0 | CC17: 1 | CD17: 0 | CE17: 0 | CF17: Adopted schedule of increases from rate study in 2021 | CG17: 5 | CH17: Flat + Constant Rate | CI17: 33.36 | CJ17: 1 | CK17: 2025 | CL17: 1 | CM17: 0.075 | CN17: 0 | CO17: 0 | CP17: 0 | CQ17: 1 | CR17: 0 | CS17: 0 | CT17: Adopted schedule of rate increases from 2021 | CU17: 4 | CV17: Flat rate plus winter average water consumption used all year | CW17: 76.22 | CX17: 2 | DO17: 1 | DP17: 3214 | DQ17: 0 | DR17: 3214 | DS17: 0 | DT17: 1276 | DU17: 0 | DV17: 105 | DW17: 1 | DX17: 0 | DY17: 1 | DZ17: 116000000 | EB17: 0 | EC17: 1 | ED17: 2.5 | EE17: 2006 | EG17: 46 | EH17: 12 | EL17: 1 | EM17: 5.7 | EN17: 1 | EO17: 1 | EP17: 1 | EQ17: 1 | EU17: Millersburg shares a treatment plant with Albany. Plant operations and production rates are reflective of both communities. Albany operates the plant. | EV17: 1 | EW17: 1 | EX17: 1 | FA17: 100 | FC17: Millersburg shares a treatment plant with Albany. Plant operations and production rates are reflective of both communities. Albany operates the plant. | FD17: 1 | FE17: 3214 | FF17: 0 | FG17: 3214 | FH17: 0 | FI17: 1276 | FJ17: 1 | FK17: 105 | FL17: 1 | FM17: 0 | FN17: 1 | FQ17: 4 | FR17: 2 | FS17: 2 | FT17: 0 | FU17: 0 | FV17: 1 | FW17: 0 | FX17: 1 | FY17: 1 | FZ17: Millersburg and Albany jointly own the wastewater plant. Albany operates the plant and administers Millersburg's industrial pretreatment program. | GK17: 1 | GL17: 2 | GM17: na | GO17: 2 | GQ17: 1 | GR17: 3 | GT17: 1 | GV17: 6 | GX17: 4 | GZ17: 3 | HC17: 4200
A18: Richland | B18: 165 | C18: 1 | D18: 12 | E18: 1 | G18: 1 | H18: 1 | I18: 1 | J18: 0 | K18: 1 | L18: 1 | M18: 2 | N18: 0 | O18: 1 | P18: 1 | Q18: 0 | R18: 0 | S18: 0 | U18: 15 | W18: 30 | Z18: 2 | AC18: 2 | AE18: 3 | AF18: 2 | AG18: 30 | AH18: If we find a month we back out all overages for the current month. | AO18: 1 | AS18: 2022 | AY18: 2 | AZ18: 2 | BC18: 1 | BD18: 1 | BE18: 0 | BF18: 0 | BG18: 0 | BH18: 0 | BJ18: 2 | BV18: 1 | BW18: 2025 | BX18: 1 | BY18: 3 | BZ18: 0 | CA18: 0 | CB18: 0 | CC18: 0 | CD18: 0 | CE18: 1 | CG18: 5 | CH18: Base Rate then overages for anything over the alloted number of gallons | CI18: 48.5 | CJ18: 1 | CU18: 1 | CW18: 32.5 | CX18: 2 | DO18: 1
A19: Scotts Mills | B19: 459 | C19: 1 | D19: 3 | E19: 4 | F19: Every other month | G19: 1 | H19: 1 | I19: 1 | J19: 0 | K19: 1 | L19: 0 | M19: 2 | N19: 1 | O19: 1 | P19: 1 | Q19: 0 | R19: 1 | S19: 0 | U19: 30 | W19: 3 | Z19: 15 | AA19: 400 | AB19: 30 | AC19: 2 | AE19: 3 | AF19: 2 | AH19: Council has to approve it but typically we look at the previous same billing period and cut 50% of the overage credited back to customer. | AJ19: 100 | AN19: 1 | AP19: 1 | AR19: 1 | AY19: 2 | AZ19: 2 | BJ19: 2 | BV19: 1 | BW19: 2025 | BX19: 1 | BY19: 0.5 | BZ19: 1 | CA19: 0 | CB19: 0 | CC19: 0 | CD19: 0 | CE19: 0 | CG19: 1 | CI19: 167.68 | CJ19: 2 | CX19: 2 | DO19: 1
A20: Elgin | B20: 1822 | C20: 3 | D20: 11 | E20: 1 | G20: 1 | H20: 1 | I20: 1 | J20: 0 | K20: 1 | L20: 0 | M20: 1 | N20: 1 | O20: 1 | P20: 1 | Q20: 0 | R20: 1 | S20: 0 | W20: 30 | Z20: 30 | AB20: 30 | AC20: 1 | AD20: City employees and first responders receive water discounts | AE20: 2 | AG20: 0
A21: Canyonville | B21: 1643 | C21: 3 | D21: 7 | E21: 1 | G21: 1 | H21: 1 | I21: 1 | J21: 0 | K21: 0 | L21: 0 | M21: 1 | N21: 1 | O21: 1 | P21: 1 | Q21: 0 | R21: 1 | S21: 0 | U21: 10 | W21: 30 | AA21: 50 | AC21: 1 | AD21: The late fee can be waived if they have not been late during that year. No discounts and no reductions given. | AE21: 3 | AF21: 1 | AH21: We do not make adjustments to water bill unless the water useage is extremely high and then we look at their monthly useage and adjust accordenly. | AI21: Usually will adjust off any of the overage that is calculated by the water overage. | AJ21: 0 | AK21: 23 | AL21: 0 | AP21: 1 | AQ21: 1 | AR21: 1 | AS21: 2023 | AT21: 2015 | AV21: 2015 | AW21: 2015 | AY21: 2 | AZ21: 4 | BB21: Owner required to pay base rate for water/wasetwater | BC21: 0 | BD21: 0 | BE21: 0 | BF21: 1 | BG21: 0 | BH21: 0 | BI21: Deposit of 2 1/2 times the base rate for water/wastewater | BJ21: 2 | BK21: 0 | BL21: 0 | BM21: 1 | BN21: 0 | BO21: 0 | BP21: 0 | BQ21: 0 | BR21: None | BS21: 2 | BT21: 2 | BU21: 2 | BV21: 1 | BW21: 2024 | BX21: 1 | BY21: 12.5 | BZ21: 1 | CA21: 0 | CB21: 0 | CC21: 0 | CD21: 0 | CE21: 0 | CG21: 5 | CH21: base rate plus consumption | CI21: 25.05 | CJ21: 1 | CK21: 2017 | CL21: 1 | CM21: 0.0959 | CN21: 1 | CO21: 0 | CP21: 0 | CQ21: 0 | CR21: 0 | CS21: 0 | CU21: 4 | CV21: flat rate (wtr 1200 cf) plus overage | CW21: 44.56 | CX21: 2 | DO21: 1
A22: Sweet Home | B22: 10116 | C22: 4 | D22: 4 | E22: 1 | G22: 1 | H22: 1 | I22: 1 | J22: 1 | K22: 1 | L22: 1 | M22: 1 | N22: 0 | O22: 1 | P22: 0 | Q22: 1 | R22: 1 | S22: 0 | U22: 5 | X22: 5 | AC22: 1 | AD22: Documentation showing low income is provided along with a completed form. | AE22: 3 | AF22: 3 | AH22: Will adjustment 2 months of bills. Must be requested within 6 months of issue. | AI22: In the winter months and adjustment based on a 12-month average. The adjustment will be made to bring the billing to the 12 month average. | AJ22: 26 | AK22: 17 | AL22: 0 | AP22: 1 | AQ22: 1 | AR22: 1 | AS22: 2023 | AT22: 2023 | AU22: 2023 | AV22: 2023 | AW22: 2023 | AX22: 2023 | AY22: 2 | AZ22: 2 | BC22: 0 | BD22: 0 | BE22: 0 | BF22: 0 | BG22: 0 | BH22: 1 | BJ22: 1 | BK22: 0 | BL22: 0 | BM22: 1 | BN22: 0 | BO22: 0 | BP22: 0 | BQ22: 0 | BR22: None | BS22: 2 | BT22: 2 | BU22: 2 | BV22: 1 | BW22: 2023 | BX22: 1 | BY22: 3 | BZ22: 0 | CA22: 1 | CB22: 1 | CC22: 0 | CD22: 0 | CE22: 1 | CG22: 1 | CI22: 52.8 | CJ22: 1 | CK22: 2023 | CL22: 1 | CM22: 3 | CN22: 1 | CO22: 1 | CP22: 1 | CQ22: 0 | CR22: 0 | CS22: 1 | CU22: 3 | CW22: 79.15 | CX22: 1 | CY22: 6 | CZ22: 1 | DA22: 3 | DB22: 2 | DC22: 1 | DD22: 0 | DE22: 1 | DF22: 0 | DG22: 0 | DH22: 1 | DJ22: 1 | DL22: 2 | DN22: 4 | DO22: 1 | DP22: 10097 | DT22: 3050 | DU22: 14 | DV22: 265 | DW22: 2 | DZ22: 3740 | EA22: 56.72 | EB22: 2 | EC22: 3 | EE22: 2010 | EH22: 6 | EI22: 1.106 | EJ22: 800000 | EK22: 1800 | EO22: 6 | EU22: 2043 | EV22: 1 | EW22: 1 | EZ22: 99.985 | FA22: 0.015 | FD22: 1 | FE22: 10097 | FI22: 3326 | FK22: 15 | FO22: 55.56 | FP22: 50.24 | FQ22: 0 | FR22: 2 | FS22: 2 | FT22: 1 | FU22: 0 | FV22: 0 | FW22: 0 | FX22: 0 | FY22: 1 | GA22: 1947 | GB22: 2023 | GC22: 1.38 | GD22: 7 | GE22: 747.7 | GF22: 7 | GG22: 2.102 | GH22: 100 | GI22: 1994 | GJ22: 1994 | GK22: 2 | GL22: 2 | GM22: N/A | GO22: 2 | GQ22: 1 | GR22: 1 | GT22: 1 | GU22: 3326 | GW22: 15 | HA22: 30.86 | HB22: 46.64 miles | HC22: 3200
A23: Maywood Park | B23: 830 | C23: 2 | D23: 2
A24: Oakridge | B24: 3167 | C24: 3 | D24: 4 | E24: 1 | G24: 1 | H24: 1 | I24: 1 | J24: 1 | K24: 1 | L24: 1 | M24: 1 | N24: 1 | O24: 1 | P24: 1 | Q24: 0 | R24: 1 | S24: 0 | U24: 0.1 | Z24: 65 | AA24: 20 | AB24: 60 | AC24: 2 | AE24: 3 | AF24: 2 | AG24: 60 | AM24: 1 | AN24: 1 | AO24: 1 | AP24: 2 | AQ24: 2 | AR24: 2 | AT24: unknown | AU24: unknown | AW24: unknown | AX24: unknown | AY24: 2 | AZ24: 2 | BC24: 0 | BD24: 0 | BE24: 0 | BF24: 1 | BG24: 0 | BH24: 0 | BI24: $6 Ambulance Service Fee | BJ24: 1 | BK24: 0 | BL24: 0 | BM24: 1 | BN24: 0 | BO24: 0 | BP24: 0 | BQ24: 0 | BR24: $6 Ambulance Service Fee | BS24: 1 | BT24: 1 | BU24: 1 | BV24: 1 | BX24: 1 | BY24: 0.03 | BZ24: 0 | CA24: 1 | CB24: 0 | CC24: 0 | CD24: 0 | CE24: 0 | CG24: 4 | CI24: 114.31 | CJ24: 1 | CL24: 1 | CM24: 3 | CN24: 0 | CO24: 1 | CP24: 0 | CQ24: 0 | CR24: 0 | CS24: 0 | CU24: 1 | CW24: 114.31 | CX24: 1 | CY24: 9 | CZ24: 1 | DA24: 0.03 | DB24: 3 | DC24: 0 | DD24: 1 | DE24: 0 | DF24: 0 | DG24: 0 | DH24: 0 | DJ24: 1 | DL24: 2 | DN24: 6.66 | DO24: 1
A25: Port Orford | B25: 1167 | C25: 2 | D25: 6 | E25: 1 | G25: 1 | H25: 1 | I25: 1 | J25: 1 | K25: 1 | L25: 0 | M25: 2 | N25: 0 | O25: 1 | P25: 1 | Q25: 0 | R25: 1 | S25: 0 | U25: 15 | W25: 7 | Z25: 90 | AC25: 2 | AE25: 3 | AF25: 3 | AG25: 90 | AH25: We only read meters once a month, so people can have one catastrophic leak forgiven each year. Sewer credits are given if the leak is not going to the sewer. | AI25: We adjust at a percentage depending where the leak happened. EX: if the overage was from a leak in the yard, 100% forgiveness on that portion would be given. If there was a leak in the yard but the plumber also fixed a leaky kitchen faucet, 50% would be given. If the shower leaked, no sewer credit would be given. It is up to the team/ me to decide based on evidence submitted.
A26: Rufus | B26: 277 | C26: 1 | D26: 8 | E26: 1 | G26: 1 | H26: 1 | I26: 1 | J26: 0 | K26: 1 | L26: 0 | M26: 2 | N26: 0 | O26: 1 | P26: 1 | Q26: 0 | R26: 1 | S26: 1 | T26: Payment arrangements | U26: 7.5 | W26: 10 | AC26: 2 | AE26: 3 | AF26: 2 | AH26: We will go back to the point leak is detected and adjust 50% of the over average usage | AP26: 1 | AQ26: 1 | AT26: Unsure | AU26: Unsure | AW26: Unsure | AX26: Unsure | AY26: 2 | AZ26: 4 | BB26: only close account at request of owner. If renter moves out, automatically goes into owner's name unless requested to close accout. | BC26: 0 | BD26: 0 | BE26: 0 | BF26: 1 | BG26: 0 | BH26: 0 | BI26: Water maintenance fee and sewer maintenance fee | BJ26: 2 | BS26: 2 | BT26: 2 | BU26: 2 | BV26: 1 | BW26: 2025 | BX26: 1 | BY26: 0.09 | BZ26: 0 | CA26: 1 | CB26: 1 | CC26: 1 | CD26: 1 | CE26: 1 | CF26: Not meeting Debt Service Requiremen | CG26: 5 | CH26: Base rate plus Usage | CJ26: 1 | CK26: 2025 | CL26: 1 | CM26: 0.1 | CN26: 0 | CO26: 1 | CP26: 1 | CQ26: 0 | CR26: 0 | CS26: 1 | CU26: 1 | CW26: 57.5 | CX26: 2 | DO26: 1 | DP26: 277 | DQ26: 1 | DT26: 140 | DV26: 17 | DW26: 2 | DZ26: 36000 | EA26: 2.21 | EB26: 6 | EC26: 2 | ED26: 0 | EE26: 1948 | EF26: 2001 | EG26: 0.8 | EH26: 0.6 | EI26: 22.4 | EJ26: 60000 | EK26: 140000 | EL26: 8 | EM26: 0.8 | EN26: 6 | EO26: 11 | EP26: 8 | EQ26: 7 | EU26: more than 50 years | EV26: 1 | EW26: 1 | EX26: 1 | FB26: 100 | FD26: 1 | FE26: 277 | FF26: 1 | FI26: 139 | FK26: 17 | FL26: 2 | FO26: 58000 | FP26: 2.1 | FQ26: 6 | FR26: 2 | FS26: 2 | FT26: 0 | FU26: 0 | FV26: 1 | FW26: 0 | FX26: 0 | FY26: 0 | FZ26: Lagoon, Natural | GA26: 1976 | GB26: 2010 | GD26: 0.09 | GE26: 9.8 | GF26: 0.036 | GG26: 0.034 | GH26: 0.75 | GI26: 2026- system is being upgraded this year to accomodate issues | GJ26: 2026 - Effulent irrigation is being replaced this fall | GK26: 1 | GL26: 2 | GM26: 70% | GO26: 2 | GS26: Wastewater Treatment plant is replacing most key items for the irrigation system. This will change exceeds capacity to 2050. | GT26: 2
A27: Arlington | B27: 678 | C27: 2 | D27: 8 | E27: 1 | G27: 1 | H27: 1 | I27: 1 | J27: 0 | K27: 1 | L27: 1 | M27: 1 | N27: 1 | O27: 1 | P27: 1 | Q27: 0 | R27: 0 | S27: 0 | U27: 5 | W27: 30 | Z27: 90 | AC27: 1 | AD27: Collections don't happen until someone leaves without paying their final bill. The City waives utility charges for our EMS, Fire Hall, and Police Office. | AE27: 3 | AF27: 2 | AH27: Depending on situation. | AY27: 2 | AZ27: 1 | BA27: They have to come to us to let us know someone has moved out. | BC27: 0 | BD27: 0 | BE27: 0 | BF27: 1 | BG27: 0 | BH27: 0 | BI27: Turn on is charged. | BJ27: 2 | BS27: 2 | BT27: 2 | BU27: 2 | BV27: 1 | BW27: 2023 | BX27: 1 | BY27: 0.05 | BZ27: 0 | CA27: 1 | CB27: 0 | CC27: 0 | CD27: 0 | CE27: 0 | CG27: 5 | CH27: Water, sewer, sanitation, and water overage usage above 7500 gallons per month. Out of town rate for water is $6 more than in town, | CI27: 42 | CJ27: 1 | CK27: 2023 | CL27: 1 | CM27: 0.05 | CN27: 0 | CO27: 1 | CP27: 0 | CQ27: 0 | CR27: 0 | CS27: 0 | CU27: 4 | CV27: Water, sewer, sanitation, and water overage usage above 7500 gallons per month. | CW27: 46 | CX27: 2 | DO27: 1
A28: Halsey | B28: 975 | C28: 2 | D28: 4 | E28: 1 | G28: 1 | H28: 1 | I28: 1 | J28: 0 | K28: 1 | L28: 0 | M28: 1 | N28: 0 | O28: 1 | P28: 1 | Q28: 0 | R28: 0 | S28: 0 | U28: 5 | Z28: 3 | AC28: 2 | AE28: 3 | AF28: 3 | AG28: 30 | AH28: We utilize historical use data and adjust to pre-leak usage | AI28: Wastewater is calculated based on water usage so when water is adjusted due to leak detection we also adjust wastewater to match the adjusted water usage rate calculated on the corrected bill | AM28: 1 | AN28: 1 | AO28: 1 | AP28: 1 | AQ28: 1 | AR28: 2 | AT28: No | AU28: No | AV28: 2022 | AW28: n/a | AX28: n/a | AY28: 2 | AZ28: 4 | BB28: If a property is vacant but the owner has not requested account closure the account remains open and is billed normally. | BC28: 1 | BD28: 1 | BE28: 0 | BF28: 1 | BG28: 1 | BH28: 1 | BI28: Turn on fees | BJ28: 1 | BS28: 1 | BT28: 1 | BU28: 2 | BV28: 1 | BW28: 2025 | BX28: 1 | BY28: 2.5 | BZ28: 0 | CA28: 1 | CB28: 1 | CC28: 0 | CD28: 0 | CE28: 1 | CG28: 1 | CI28: 53.34 | CJ28: 1 | CK28: 2025 | CL28: 1 | CM28: 2.5 | CN28: 0 | CO28: 1 | CP28: 1 | CQ28: 0 | CR28: 0 | CS28: 1 | CU28: 4 | CV28: Flat rate based on water consumption in the month billed | CW28: 47 | CX28: 1 | DB28: 3 | DJ28: 1 | DL28: 2 | DN28: 3 | DO28: 1
A29: Mt. Vernon | B29: 549 | C29: 2 | D29: 12 | E29: 1 | G29: 1 | H29: 1 | I29: 1 | J29: 0 | K29: 1 | L29: 1 | M29: 2 | N29: 1 | O29: 1 | P29: 1 | Q29: 0 | R29: 0 | S29: 0 | W29: 15 | AB29: 15 | AC29: 2 | AE29: 3 | AF29: 2 | AH29: Most people find it by then.
A30: Roseburg | B30: 23910 | C30: 5 | D30: 7 | E30: 4 | F30: every 2 months | G30: 1 | H30: 1 | I30: 1 | J30: 1 | K30: 1 | L30: 0 | M30: 1 | N30: 1 | O30: 1 | P30: 1 | Q30: 0 | R30: 0 | S30: 0 | U30: 20 | W30: 30 | Z30: 45 | AB30: 75 | AC30: 2 | AE30: 3 | AF30: 2 | AG30: 1 | AM30: 1 | AN30: 1 | AO30: 1 | AP30: 1 | AR30: 1 | AS30: 2015 | AT30: n/a | AU30: unknown | AV30: 2015 | AW30: n/a | AX30: unknown | AY30: 2 | AZ30: 4 | BB30: account reverts to the property owner who is responsible for the base water fees and the storm water fees | BC30: 0 | BD30: 1 | BE30: 0 | BF30: 0 | BG30: 1 | BH30: 1 | BJ30: 1 | BS30: 1 | BU30: 1 | BV30: 1 | BW30: 2025 | BX30: 1 | BY30: 2.2 | BZ30: 0 | CA30: 1 | CB30: 0 | CC30: 0 | CD30: 0 | CE30: 0 | CG30: 1 | CI30: 34.21 | CJ30: 2 | CX30: 1 | CY30: 7 | CZ30: 1 | DA30: 2.2 | DB30: 2 | DC30: 0 | DD30: 1 | DE30: 0 | DF30: 0 | DG30: 0 | DH30: 0 | DJ30: 1 | DL30: 1 | DM30: by the amount of permanent reduction to the runoff coefficient for the property due to the retention system. | DN30: 9.43 | DO30: 1 | DP30: 23795 | DQ30: 6000 | DT30: 7498 | DU30: 2466 | DV30: 1388 | DW30: 3 | DX30: 107 | DY30: 3 | DZ30: 120000 | EA30: 195 | EB30: 21 | EC30: 27 | ED30: 5 | EE30: 1935 | EF30: 1992 | EG30: 20 | EH30: 12 | EI30: 5.814 | EJ30: 2.061 | EK30: 8.872 | EL30: 1 | EM30: 11.2 | EN30: 1 | EO30: 1 | EP30: 1 | EQ30: 1 | ER30: N/A | ES30: 0 | ET30: 0 | EU30: It has not exceeded capacity | EV30: 1 | EW30: 1 | EX30: 1 | EZ30: 0 | FA30: 0.5 | FB30: 99.5 | FC30: none | FD30: 2 | GT30: 1 | GU30: 7498 | GV30: 1 | GW30: 1388 | GX30: 1 | GY30: 107 | GZ30: 1 | HA30: 104 | HB30: unknown | HC30: 3000 | HD30: none
A31: Ione | B31: 342 | C31: 1 | D31: 11 | E31: 1 | G31: 1 | H31: 1 | I31: 1 | J31: 1 | K31: 1 | L31: 0 | M31: 2 | N31: 1 | O31: 1 | P31: 1 | Q31: 0 | R31: 0 | S31: 0 | U31: 25 | W31: 30 | Z31: 60 | AB31: 75 | AC31: 2 | AE31: 3 | AF31: 2 | AG31: 30 | AJ31: 75 | AP31: 1 | AY31: 2 | AZ31: 2 | BC31: 0 | BD31: 0 | BE31: 0 | BF31: 0 | BG31: 1 | BH31: 0 | BJ31: 2 | BS31: 2 | BV31: 1 | BW31: 2021 | BX31: 1 | BY31: 0.02 | BZ31: 0 | CA31: 1 | CB31: 1 | CC31: 0 | CD31: 0 | CE31: 0 | CG31: 1 | CI31: 47.85 | CJ31: 2 | CX31: 2 | DO31: 1
A32: Joseph | B32: 1182 | C32: 2 | D32: 11 | E32: 1 | G32: 1 | H32: 1 | I32: 1 | J32: 0 | K32: 1 | L32: 1 | M32: 1 | N32: 1 | O32: 1 | P32: 1 | Q32: 0 | R32: 0 | S32: 0
